2023-01-12 21:03:05.922 | ERROR    | src.session:__init__:35 - Authentication failed: Unknown error (AUTH; no sid). Please send a bugreport to GitHub: https://github.com/python273/vk_api/issues | Account: kos161rus@rambler.ru
